Workbook

Sheet test
A1: Finca | B1: Qty | C1: Type of Box | D1: Cantidad_Min | E1: Cantidad_QB | F1: Variedad | G1: Nombre | H1: Color | I1: Cost | J1: Markup | K1: Precio | L1: Guia | M1: FechaEntrega | N1: Duties | O1: Origen | P1: Box | Q1: img | R1: Transport | S1: Largo2 | T1: Ancho | U1: Alto | V1: Volumen | W1: Transport2 | X1: Import Duties | Y1: Total | Z1: FincaID | AA1: Inventarios | AB1: SendEmail | AC1: Comments | AD1: Standing Orders
A2: Agrirose | B2: 3 | C2: EB | D2: 120 | E2: 120 | F2: Ranunculus/Anemones | G2: ="Assorted Colors " & _xlfn.XLOOKUP(Main[[#This Row],[FechaEntrega]], Guias[Fecha], Guias[Llegada]) -> Assorted Colors (T/W) | H2: PO107154 | I2: 0.7 | J2: =_xlfn.LET( _xlpm.result, 1-((Main[[#This Row],[Cost]]+Main[[#This Row],[Duties]]+Main[[#This Row],[Transport]])/((Main[[#This Row],[Precio]]*0.96))), IF(_xlpm.result<0, "BAJO", IF(_xlpm.result>1, "ALTO", _xlpm.result)) ) -> 0.30350099 | K2: 1.69 | L2: {=_xlfn.LET( _xlpm.DiaSemana, WEEKDAY(Main[[#This Row],[FechaEntrega]], 2), _xlpm.CajaEcuador, OR(Main[[#This Row],[Type of Box]]="QB", Main[[#This Row],[Type of Box]]="EB", Main[[#This Row],[Type of Box]]="HB", Main[[#This Row],[Type of Box]]="SB"), _xlpm.CajaColombia, OR(Main[[#This Row],[Type of Box]]="QB2", Main[[#This Row],[Type of Box]]="EB2"), _xlpm.EsTF, ISNUMBER(SEARCH("T/F", Main[[#This Row],[Nombre]])), _xlpm.FincaCol, OR(Main[[#This Row],[Finca]]="Plazoleta", Main[[#This Row],[Finca]]="Flowers Party", Main[[#This Row],[Finca]]="HydranFlowers", Main[[#This Row],[Finca]]="Alexandra Farms", Main[[#This Row],[Finca]]="Circasia S.A.S.", Main[[#This Row],[Finca]]="Vuelven S.A.S.", Main[[#This Row],[Finca]]="Cultivos del Norte", Main[[#This Row],[Finca]]="La Conchita"), _xlpm.DiaGuia, _xlfn.IFS( AND(_xlpm.DiaSemana=1, _xlpm.CajaEcuador), "Lunes", AND(_xlpm.DiaSemana=1, _xlpm.CajaColombia), "Lunes", AND(_xlpm.DiaSemana=2, _xlpm.CajaEcuador), "Martes", AND(_xlpm.DiaSemana=2, _xlpm.CajaColombia), "Lunes", _xlpm.DiaSemana=3, "Miercoles", AND(_xlpm.DiaSemana=4, _xlpm.CajaEcuador), "Jueves", AND(_xlpm.DiaSemana=4, _xlpm.CajaColombia), "Miercoles", AND(_xlpm.DiaSemana=5, _xlpm.CajaEcuador), "Viernes", AND(_xlpm.DiaSemana=5, _xlpm.CajaColombia), "Jueves", AND(_xlpm.DiaSemana=6, _xlpm.CajaEcuador, _xlpm.EsTF), "Sabado B", AND(_xlpm.DiaSemana=6, _xlpm.CajaEcuador), "Viernes", AND(_xlpm.DiaSemana=6, _xlpm.CajaColombia), "Viernes", TRUE, "" ), _xlpm.ColGuia, _xlfn.IFS( _xlpm.DiaSemana=3, Guias[Ecuador], _xlpm.CajaColombia, Guias[Colombia], TRUE, Guias[Ecuador] ), _xlpm.VuelosError, IFERROR(_xlfn.XLOOKUP(_xlpm.DiaGuia, Guias[Día], Guias[Vuelos])="***Error de Fecha***", FALSE), _xlpm.SemanaIncorrecta, _xlfn.ISOWEEKNUM(Main[[#This Row],[FechaEntrega]]-2) <> Guias!$M$2, IF(_xlpm.SemanaIncorrecta, "ERROR S", IF(ISNA(MATCH(Main[[#This Row],[FechaEntrega]], Guias[Fecha], 0)), "ERROR F", IF(_xlfn.XOR(_xlpm.FincaCol, _xlpm.CajaColombia), "ERROR P", IF(_xlpm.DiaGuia="", "", IF(_xlpm.VuelosError, "ERROR V", _xlfn.XLOOKUP(_xlpm.DiaGuia, Guias[Día], _xlpm.ColGuia) ) ) ) ) ) )} -> 16977 | M2: =Guias!$B$3 -> 46310 | N2: =ROUNDUP((Main[[#This Row],[Cost]]*Main[[#This Row],[Import Duties]]),2) -> 0.12 | O2: 0 | P2: 1 | Q2: 0 | R2: =ROUNDUP(Main[[#This Row],[Transport2]]/Main[[#This Row],[Cantidad_Min]],2) -> 0.31 | S2: =_xlfn.XLOOKUP(Main[[#This Row],[Type of Box]], Cajas[Nombre], Cajas[Largo]) -> 105 | T2: =_xlfn.XLOOKUP(Main[[#This Row],[Type of Box]], Cajas[Nombre], Cajas[Ancho]) -> 17 | U2: =_xlfn.XLOOKUP(Main[[#This Row],[Type of Box]], Cajas[Nombre], Cajas[Alto]) -> 17 | V2: =IF(Main[[#This Row],[Type of Box]]="", "", IF(OR(Main[[#This Row],[Type of Box]]="QB", Main[[#This Row],[Type of Box]]="EB", Main[[#This Row],[Type of Box]]="HB", Main[[#This Row],[Type of Box]]="QB2", Main[[#This Row],[Type of Box]]="EB2", Main[[#This Row],[Type of Box]]="SB"), (Main[[#This Row],[Largo2]]*Main[[#This Row],[Ancho]]*Main[[#This Row],[Alto]])/6000, ((Main[[#This Row],[Largo2]]+Sheet1!$U$2)*(Main[[#This Row],[Ancho]]+Sheet1!$U$2)*(Main[[#This Row],[Alto]]+Sheet1!$U$2))/6000)) -> 5.0575 | W2: =ROUNDUP(((Main[[#This Row],[Volumen]]*5.25))*1.36,2) -> 36.12 | X2: 0.1586 | Y2: =Main[[#This Row],[Cantidad_Min]]*Main[[#This Row],[Precio]]*Main[[#This Row],[Qty]] -> 608.4 | Z2: =_xlfn.XLOOKUP(Main[[#This Row],[Finca]], Fincas[Nombre], Fincas[ID]) -> 53 | AA2: {=_xlfn.LET( _xlpm.txt, Main[[#This Row],[Standing Orders]], _xlpm.q2num, IFERROR(VALUE(Guias!$M$2), ""), _xlpm.q2txt, UPPER(Guias!$M$2), _xlpm.weekIsOdd, IF(_xlpm.q2num<>"", MOD(_xlpm.q2num,2)=1, IF(ISNUMBER(FIND("IMPAR", _xlpm.q2txt)), TRUE, IF(ISNUMBER(FIND("PAR", _xlpm.q2txt)), FALSE, TRUE))), _xlpm.parts, IF(TRIM(_xlpm.txt)="", "", _xlfn.TOCOL(_xlfn.TEXTSPLIT(SUBSTITUTE(_xlpm.txt, CHAR(160), " "), ";"), 1)), _xlpm.build, IF(_xlfn.VALUETOTEXT(_xlpm.parts)="", "", _xlfn.MAP(_xlpm.parts, _xlfn.LAMBDA(_xlpm.r, _xlfn.LET( _xlpm.s, TRIM(_xlpm.r), _xlpm.s_upper, UPPER(_xlpm.s), _xlpm.p_marker, IF(ISNUMBER(FIND("(*IMPAR)", _xlpm.s_upper)), "impar", IF(ISNUMBER(FIND("(*PAR)", _xlpm.s_upper)), "par", "")), _xlpm.allow, IF(_xlpm.p_marker="", TRUE, IF(_xlpm.p_marker="impar", _xlpm.weekIsOdd, NOT(_xlpm.weekIsOdd))), IF(NOT(_xlpm.allow), "", _xlfn.LET( _xlpm.num, IFERROR(VALUE(LEFT(_xlpm.s, FIND(" ", _xlpm.s & " ")-1)), 0), _xlpm.rawname, TRIM(IFERROR(_xlfn.TEXTAFTER(_xlpm.s, " "), "")), _xlpm.name_pre, IFERROR(_xlfn.TEXTBEFORE(_xlpm.rawname, "["), _xlpm.rawname), _xlpm.name, TRIM(IFERROR(_xlfn.TEXTBEFORE(_xlpm.name_pre, "("), _xlpm.name_pre)), _xlpm.id, _xlfn.XLOOKUP(_xlpm.name, Vendedores[Fragmento], Vendedores[ID], ""), IF(OR(_xlpm.id="", _xlpm.num<=0), "", LEFT(REPT(_xlpm.id & ",", _xlpm.num), LEN(REPT(_xlpm.id & ",", _xlpm.num)) - 1)) ) ) ) ))), _xlpm.resultado, _xlfn.TEXTJOIN(",", TRUE, _xlpm.build), IF(_xlpm.resultado="", "", _xlpm.resultado & ",") )} | AB2: Y
A3: Agrocoex | B3: 2 | C3: QB | D3: 120 | E3: 120 | F3: Larkspur | G3: ="Assorted Colors " & _xlfn.XLOOKUP(Main[[#This Row],[FechaEntrega]], Guias[Fecha], Guias[Llegada]) -> Assorted Colors (T/W) | H3: PO107155 | I3: 0.4 | J3: =_xlfn.LET( _xlpm.result, 1-((Main[[#This Row],[Cost]]+Main[[#This Row],[Duties]]+Main[[#This Row],[Transport]])/((Main[[#This Row],[Precio]]*0.96))), IF(_xlpm.result<0, "BAJO", IF(_xlpm.result>1, "ALTO", _xlpm.result)) ) -> 0.26805556 | K3: 1.4516129 | L3: {=_xlfn.LET( _xlpm.DiaSemana, WEEKDAY(Main[[#This Row],[FechaEntrega]], 2), _xlpm.CajaEcuador, OR(Main[[#This Row],[Type of Box]]="QB", Main[[#This Row],[Type of Box]]="EB", Main[[#This Row],[Type of Box]]="HB", Main[[#This Row],[Type of Box]]="SB"), _xlpm.CajaColombia, OR(Main[[#This Row],[Type of Box]]="QB2", Main[[#This Row],[Type of Box]]="EB2"), _xlpm.EsTF, ISNUMBER(SEARCH("T/F", Main[[#This Row],[Nombre]])), _xlpm.FincaCol, OR(Main[[#This Row],[Finca]]="Plazoleta", Main[[#This Row],[Finca]]="Flowers Party", Main[[#This Row],[Finca]]="HydranFlowers", Main[[#This Row],[Finca]]="Alexandra Farms", Main[[#This Row],[Finca]]="Circasia S.A.S.", Main[[#This Row],[Finca]]="Vuelven S.A.S.", Main[[#This Row],[Finca]]="Cultivos del Norte", Main[[#This Row],[Finca]]="La Conchita"), _xlpm.DiaGuia, _xlfn.IFS( AND(_xlpm.DiaSemana=1, _xlpm.CajaEcuador), "Lunes", AND(_xlpm.DiaSemana=1, _xlpm.CajaColombia), "Lunes", AND(_xlpm.DiaSemana=2, _xlpm.CajaEcuador), "Martes", AND(_xlpm.DiaSemana=2, _xlpm.CajaColombia), "Lunes", _xlpm.DiaSemana=3, "Miercoles", AND(_xlpm.DiaSemana=4, _xlpm.CajaEcuador), "Jueves", AND(_xlpm.DiaSemana=4, _xlpm.CajaColombia), "Miercoles", AND(_xlpm.DiaSemana=5, _xlpm.CajaEcuador), "Viernes", AND(_xlpm.DiaSemana=5, _xlpm.CajaColombia), "Jueves", AND(_xlpm.DiaSemana=6, _xlpm.CajaEcuador, _xlpm.EsTF), "Sabado B", AND(_xlpm.DiaSemana=6, _xlpm.CajaEcuador), "Viernes", AND(_xlpm.DiaSemana=6, _xlpm.CajaColombia), "Viernes", TRUE, "" ), _xlpm.ColGuia, _xlfn.IFS( _xlpm.DiaSemana=3, Guias[Ecuador], _xlpm.CajaColombia, Guias[Colombia], TRUE, Guias[Ecuador] ), _xlpm.VuelosError, IFERROR(_xlfn.XLOOKUP(_xlpm.DiaGuia, Guias[Día], Guias[Vuelos])="***Error de Fecha***", FALSE), _xlpm.SemanaIncorrecta, _xlfn.ISOWEEKNUM(Main[[#This Row],[FechaEntrega]]-2) <> Guias!$M$2, IF(_xlpm.SemanaIncorrecta, "ERROR S", IF(ISNA(MATCH(Main[[#This Row],[FechaEntrega]], Guias[Fecha], 0)), "ERROR F", IF(_xlfn.XOR(_xlpm.FincaCol, _xlpm.CajaColombia), "ERROR P", IF(_xlpm.DiaGuia="", "", IF(_xlpm.VuelosError, "ERROR V", _xlfn.XLOOKUP(_xlpm.DiaGuia, Guias[Día], _xlpm.ColGuia) ) ) ) ) ) )} -> 16977 | M3: =Guias!$B$3 -> 46310 | N3: =ROUNDUP((Main[[#This Row],[Cost]]*Main[[#This Row],[Import Duties]]),2) -> 0.07 | O3: 0 | P3: 1 | Q3: 0 | R3: =ROUNDUP(Main[[#This Row],[Transport2]]/Main[[#This Row],[Cantidad_Min]],2) -> 0.55 | S3: =_xlfn.XLOOKUP(Main[[#This Row],[Type of Box]], Cajas[Nombre], Cajas[Largo]) -> 99 | T3: =_xlfn.XLOOKUP(Main[[#This Row],[Type of Box]], Cajas[Nombre], Cajas[Ancho]) -> 35 | U3: =_xlfn.XLOOKUP(Main[[#This Row],[Type of Box]], Cajas[Nombre], Cajas[Alto]) -> 16 | V3: =IF(Main[[#This Row],[Type of Box]]="", "", IF(OR(Main[[#This Row],[Type of Box]]="QB", Main[[#This Row],[Type of Box]]="EB", Main[[#This Row],[Type of Box]]="HB", Main[[#This Row],[Type of Box]]="QB2", Main[[#This Row],[Type of Box]]="EB2", Main[[#This Row],[Type of Box]]="SB"), (Main[[#This Row],[Largo2]]*Main[[#This Row],[Ancho]]*Main[[#This Row],[Alto]])/6000, ((Main[[#This Row],[Largo2]]+Sheet1!$U$2)*(Main[[#This Row],[Ancho]]+Sheet1!$U$2)*(Main[[#This Row],[Alto]]+Sheet1!$U$2))/6000)) -> 9.24 | W3: =ROUNDUP(((Main[[#This Row],[Volumen]]*5.25))*1.36,2) -> 65.98 | X3: 0.1586 | Y3: =Main[[#This Row],[Cantidad_Min]]*Main[[#This Row],[Precio]]*Main[[#This Row],[Qty]] -> 348.3871 | Z3: =_xlfn.XLOOKUP(Main[[#This Row],[Finca]], Fincas[Nombre], Fincas[ID]) -> 49 | AA3: {=_xlfn.LET( _xlpm.txt, Main[[#This Row],[Standing Orders]], _xlpm.q2num, IFERROR(VALUE(Guias!$M$2), ""), _xlpm.q2txt, UPPER(Guias!$M$2), _xlpm.weekIsOdd, IF(_xlpm.q2num<>"", MOD(_xlpm.q2num,2)=1, IF(ISNUMBER(FIND("IMPAR", _xlpm.q2txt)), TRUE, IF(ISNUMBER(FIND("PAR", _xlpm.q2txt)), FALSE, TRUE))), _xlpm.parts, IF(TRIM(_xlpm.txt)="", "", _xlfn.TOCOL(_xlfn.TEXTSPLIT(SUBSTITUTE(_xlpm.txt, CHAR(160), " "), ";"), 1)), _xlpm.build, IF(_xlfn.VALUETOTEXT(_xlpm.parts)="", "", _xlfn.MAP(_xlpm.parts, _xlfn.LAMBDA(_xlpm.r, _xlfn.LET( _xlpm.s, TRIM(_xlpm.r), _xlpm.s_upper, UPPER(_xlpm.s), _xlpm.p_marker, IF(ISNUMBER(FIND("(*IMPAR)", _xlpm.s_upper)), "impar", IF(ISNUMBER(FIND("(*PAR)", _xlpm.s_upper)), "par", "")), _xlpm.allow, IF(_xlpm.p_marker="", TRUE, IF(_xlpm.p_marker="impar", _xlpm.weekIsOdd, NOT(_xlpm.weekIsOdd))), IF(NOT(_xlpm.allow), "", _xlfn.LET( _xlpm.num, IFERROR(VALUE(LEFT(_xlpm.s, FIND(" ", _xlpm.s & " ")-1)), 0), _xlpm.rawname, TRIM(IFERROR(_xlfn.TEXTAFTER(_xlpm.s, " "), "")), _xlpm.name_pre, IFERROR(_xlfn.TEXTBEFORE(_xlpm.rawname, "["), _xlpm.rawname), _xlpm.name, TRIM(IFERROR(_xlfn.TEXTBEFORE(_xlpm.name_pre, "("), _xlpm.name_pre)), _xlpm.id, _xlfn.XLOOKUP(_xlpm.name, Vendedores[Fragmento], Vendedores[ID], ""), IF(OR(_xlpm.id="", _xlpm.num<=0), "", LEFT(REPT(_xlpm.id & ",", _xlpm.num), LEN(REPT(_xlpm.id & ",", _xlpm.num)) - 1)) ) ) ) ))), _xlpm.resultado, _xlfn.TEXTJOIN(",", TRUE, _xlpm.build), IF(_xlpm.resultado="", "", _xlpm.resultado & ",") )} | AB3: Y
A4: Agrogana | B4: 1 | C4: EB | D4: 1 | E4: 1 | F4: Hannas Mix | G4: ="Ran. Pompon/Limonium/Statice/Freesia/Delph/Dianthus/Sp. Roses x 120 " & _xlfn.XLOOKUP(Main[[#This Row],[FechaEntrega]], Guias[Fecha], Guias[Llegada]) -> Ran. Pompon/Limonium/Statice/Freesia/Delph/Dianthus/Sp. Roses x 120 (T/W) | H4: PO107156 | I4: 46 | J4: =_xlfn.LET( _xlpm.result, 1-((Main[[#This Row],[Cost]]+Main[[#This Row],[Duties]]+Main[[#This Row],[Transport]])/((Main[[#This Row],[Precio]]*0.96))), IF(_xlpm.result<0, "BAJO", IF(_xlpm.result>1, "ALTO", _xlpm.result)) ) -> 0.28343432 | K4: 129.98925 | L4: {=_xlfn.LET( _xlpm.DiaSemana, WEEKDAY(Main[[#This Row],[FechaEntrega]], 2), _xlpm.CajaEcuador, OR(Main[[#This Row],[Type of Box]]="QB", Main[[#This Row],[Type of Box]]="EB", Main[[#This Row],[Type of Box]]="HB", Main[[#This Row],[Type of Box]]="SB"), _xlpm.CajaColombia, OR(Main[[#This Row],[Type of Box]]="QB2", Main[[#This Row],[Type of Box]]="EB2"), _xlpm.EsTF, ISNUMBER(SEARCH("T/F", Main[[#This Row],[Nombre]])), _xlpm.FincaCol, OR(Main[[#This Row],[Finca]]="Plazoleta", Main[[#This Row],[Finca]]="Flowers Party", Main[[#This Row],[Finca]]="HydranFlowers", Main[[#This Row],[Finca]]="Alexandra Farms", Main[[#This Row],[Finca]]="Circasia S.A.S.", Main[[#This Row],[Finca]]="Vuelven S.A.S.", Main[[#This Row],[Finca]]="Cultivos del Norte", Main[[#This Row],[Finca]]="La Conchita"), _xlpm.DiaGuia, _xlfn.IFS( AND(_xlpm.DiaSemana=1, _xlpm.CajaEcuador), "Lunes", AND(_xlpm.DiaSemana=1, _xlpm.CajaColombia), "Lunes", AND(_xlpm.DiaSemana=2, _xlpm.CajaEcuador), "Martes", AND(_xlpm.DiaSemana=2, _xlpm.CajaColombia), "Lunes", _xlpm.DiaSemana=3, "Miercoles", AND(_xlpm.DiaSemana=4, _xlpm.CajaEcuador), "Jueves", AND(_xlpm.DiaSemana=4, _xlpm.CajaColombia), "Miercoles", AND(_xlpm.DiaSemana=5, _xlpm.CajaEcuador), "Viernes", AND(_xlpm.DiaSemana=5, _xlpm.CajaColombia), "Jueves", AND(_xlpm.DiaSemana=6, _xlpm.CajaEcuador, _xlpm.EsTF), "Sabado B", AND(_xlpm.DiaSemana=6, _xlpm.CajaEcuador), "Viernes", AND(_xlpm.DiaSemana=6, _xlpm.CajaColombia), "Viernes", TRUE, "" ), _xlpm.ColGuia, _xlfn.IFS( _xlpm.DiaSemana=3, Guias[Ecuador], _xlpm.CajaColombia, Guias[Colombia], TRUE, Guias[Ecuador] ), _xlpm.VuelosError, IFERROR(_xlfn.XLOOKUP(_xlpm.DiaGuia, Guias[Día], Guias[Vuelos])="***Error de Fecha***", FALSE), _xlpm.SemanaIncorrecta, _xlfn.ISOWEEKNUM(Main[[#This Row],[FechaEntrega]]-2) <> Guias!$M$2, IF(_xlpm.SemanaIncorrecta, "ERROR S", IF(ISNA(MATCH(Main[[#This Row],[FechaEntrega]], Guias[Fecha], 0)), "ERROR F", IF(_xlfn.XOR(_xlpm.FincaCol, _xlpm.CajaColombia), "ERROR P", IF(_xlpm.DiaGuia="", "", IF(_xlpm.VuelosError, "ERROR V", _xlfn.XLOOKUP(_xlpm.DiaGuia, Guias[Día], _xlpm.ColGuia) ) ) ) ) ) )} -> 16977 | M4: =Guias!$B$3 -> 46310 | N4: =ROUNDUP((Main[[#This Row],[Cost]]*Main[[#This Row],[Import Duties]]),2) -> 7.3 | O4: 0 | P4: 1 | Q4: 0 | R4: =ROUNDUP(Main[[#This Row],[Transport2]]/Main[[#This Row],[Cantidad_Min]],2) -> 36.12 | S4: =_xlfn.XLOOKUP(Main[[#This Row],[Type of Box]], Cajas[Nombre], Cajas[Largo]) -> 105 | T4: =_xlfn.XLOOKUP(Main[[#This Row],[Type of Box]], Cajas[Nombre], Cajas[Ancho]) -> 17 | U4: =_xlfn.XLOOKUP(Main[[#This Row],[Type of Box]], Cajas[Nombre], Cajas[Alto]) -> 17 | V4: =IF(Main[[#This Row],[Type of Box]]="", "", IF(OR(Main[[#This Row],[Type of Box]]="QB", Main[[#This Row],[Type of Box]]="EB", Main[[#This Row],[Type of Box]]="HB", Main[[#This Row],[Type of Box]]="QB2", Main[[#This Row],[Type of Box]]="EB2", Main[[#This Row],[Type of Box]]="SB"), (Main[[#This Row],[Largo2]]*Main[[#This Row],[Ancho]]*Main[[#This Row],[Alto]])/6000, ((Main[[#This Row],[Largo2]]+Sheet1!$U$2)*(Main[[#This Row],[Ancho]]+Sheet1!$U$2)*(Main[[#This Row],[Alto]]+Sheet1!$U$2))/6000)) -> 5.0575 | W4: =ROUNDUP(((Main[[#This Row],[Volumen]]*5.25))*1.36,2) -> 36.12 | X4: 0.1586 | Y4: =Main[[#This Row],[Cantidad_Min]]*Main[[#This Row],[Precio]]*Main[[#This Row],[Qty]] -> 129.98925 | Z4: =_xlfn.XLOOKUP(Main[[#This Row],[Finca]], Fincas[Nombre], Fincas[ID]) -> 77 | AA4: {=_xlfn.LET( _xlpm.txt, Main[[#This Row],[Standing Orders]], _xlpm.q2num, IFERROR(VALUE(Guias!$M$2), ""), _xlpm.q2txt, UPPER(Guias!$M$2), _xlpm.weekIsOdd, IF(_xlpm.q2num<>"", MOD(_xlpm.q2num,2)=1, IF(ISNUMBER(FIND("IMPAR", _xlpm.q2txt)), TRUE, IF(ISNUMBER(FIND("PAR", _xlpm.q2txt)), FALSE, TRUE))), _xlpm.parts, IF(TRIM(_xlpm.txt)="", "", _xlfn.TOCOL(_xlfn.TEXTSPLIT(SUBSTITUTE(_xlpm.txt, CHAR(160), " "), ";"), 1)), _xlpm.build, IF(_xlfn.VALUETOTEXT(_xlpm.parts)="", "", _xlfn.MAP(_xlpm.parts, _xlfn.LAMBDA(_xlpm.r, _xlfn.LET( _xlpm.s, TRIM(_xlpm.r), _xlpm.s_upper, UPPER(_xlpm.s), _xlpm.p_marker, IF(ISNUMBER(FIND("(*IMPAR)", _xlpm.s_upper)), "impar", IF(ISNUMBER(FIND("(*PAR)", _xlpm.s_upper)), "par", "")), _xlpm.allow, IF(_xlpm.p_marker="", TRUE, IF(_xlpm.p_marker="impar", _xlpm.weekIsOdd, NOT(_xlpm.weekIsOdd))), IF(NOT(_xlpm.allow), "", _xlfn.LET( _xlpm.num, IFERROR(VALUE(LEFT(_xlpm.s, FIND(" ", _xlpm.s & " ")-1)), 0), _xlpm.rawname, TRIM(IFERROR(_xlfn.TEXTAFTER(_xlpm.s, " "), "")), _xlpm.name_pre, IFERROR(_xlfn.TEXTBEFORE(_xlpm.rawname, "["), _xlpm.rawname), _xlpm.name, TRIM(IFERROR(_xlfn.TEXTBEFORE(_xlpm.name_pre, "("), _xlpm.name_pre)), _xlpm.id, _xlfn.XLOOKUP(_xlpm.name, Vendedores[Fragmento], Vendedores[ID], ""), IF(OR(_xlpm.id="", _xlpm.num<=0), "", LEFT(REPT(_xlpm.id & ",", _xlpm.num), LEN(REPT(_xlpm.id & ",", _xlpm.num)) - 1)) ) ) ) ))), _xlpm.resultado, _xlfn.TEXTJOIN(",", TRUE, _xlpm.build), IF(_xlpm.resultado="", "", _xlpm.resultado & ",") )} -> fparamo, | AB4: Y | AC4: Natalias Mix | AD4: 1 Fausto [Florist in the Garden WA]
A5: Agrogana | B5: 2 | C5: EB | D5: 1 | E5: 1 | F5: Hannas Mix | G5: ="Ran. Pompon/Limonium/Statice/Freesia/Delph/Dianthus/Sp. Roses x 120 " & _xlfn.XLOOKUP(Main[[#This Row],[FechaEntrega]], Guias[Fecha], Guias[Llegada]) -> Ran. Pompon/Limonium/Statice/Freesia/Delph/Dianthus/Sp. Roses x 120 (T/W) | H5: PO107157 | I5: 46 | J5: =_xlfn.LET( _xlpm.result, 1-((Main[[#This Row],[Cost]]+Main[[#This Row],[Duties]]+Main[[#This Row],[Transport]])/((Main[[#This Row],[Precio]]*0.96))), IF(_xlpm.result<0, "BAJO", IF(_xlpm.result>1, "ALTO", _xlpm.result)) ) -> 0.28343432 | K5: 129.98925 | L5: {=_xlfn.LET( _xlpm.DiaSemana, WEEKDAY(Main[[#This Row],[FechaEntrega]], 2), _xlpm.CajaEcuador, OR(Main[[#This Row],[Type of Box]]="QB", Main[[#This Row],[Type of Box]]="EB", Main[[#This Row],[Type of Box]]="HB", Main[[#This Row],[Type of Box]]="SB"), _xlpm.CajaColombia, OR(Main[[#This Row],[Type of Box]]="QB2", Main[[#This Row],[Type of Box]]="EB2"), _xlpm.EsTF, ISNUMBER(SEARCH("T/F", Main[[#This Row],[Nombre]])), _xlpm.FincaCol, OR(Main[[#This Row],[Finca]]="Plazoleta", Main[[#This Row],[Finca]]="Flowers Party", Main[[#This Row],[Finca]]="HydranFlowers", Main[[#This Row],[Finca]]="Alexandra Farms", Main[[#This Row],[Finca]]="Circasia S.A.S.", Main[[#This Row],[Finca]]="Vuelven S.A.S.", Main[[#This Row],[Finca]]="Cultivos del Norte", Main[[#This Row],[Finca]]="La Conchita"), _xlpm.DiaGuia, _xlfn.IFS( AND(_xlpm.DiaSemana=1, _xlpm.CajaEcuador), "Lunes", AND(_xlpm.DiaSemana=1, _xlpm.CajaColombia), "Lunes", AND(_xlpm.DiaSemana=2, _xlpm.CajaEcuador), "Martes", AND(_xlpm.DiaSemana=2, _xlpm.CajaColombia), "Lunes", _xlpm.DiaSemana=3, "Miercoles", AND(_xlpm.DiaSemana=4, _xlpm.CajaEcuador), "Jueves", AND(_xlpm.DiaSemana=4, _xlpm.CajaColombia), "Miercoles", AND(_xlpm.DiaSemana=5, _xlpm.CajaEcuador), "Viernes", AND(_xlpm.DiaSemana=5, _xlpm.CajaColombia), "Jueves", AND(_xlpm.DiaSemana=6, _xlpm.CajaEcuador, _xlpm.EsTF), "Sabado B", AND(_xlpm.DiaSemana=6, _xlpm.CajaEcuador), "Viernes", AND(_xlpm.DiaSemana=6, _xlpm.CajaColombia), "Viernes", TRUE, "" ), _xlpm.ColGuia, _xlfn.IFS( _xlpm.DiaSemana=3, Guias[Ecuador], _xlpm.CajaColombia, Guias[Colombia], TRUE, Guias[Ecuador] ), _xlpm.VuelosError, IFERROR(_xlfn.XLOOKUP(_xlpm.DiaGuia, Guias[Día], Guias[Vuelos])="***Error de Fecha***", FALSE), _xlpm.SemanaIncorrecta, _xlfn.ISOWEEKNUM(Main[[#This Row],[FechaEntrega]]-2) <> Guias!$M$2, IF(_xlpm.SemanaIncorrecta, "ERROR S", IF(ISNA(MATCH(Main[[#This Row],[FechaEntrega]], Guias[Fecha], 0)), "ERROR F", IF(_xlfn.XOR(_xlpm.FincaCol, _xlpm.CajaColombia), "ERROR P", IF(_xlpm.DiaGuia="", "", IF(_xlpm.VuelosError, "ERROR V", _xlfn.XLOOKUP(_xlpm.DiaGuia, Guias[Día], _xlpm.ColGuia) ) ) ) ) ) )} -> 16977 | M5: =Guias!$B$3 -> 46310 | N5: =ROUNDUP((Main[[#This Row],[Cost]]*Main[[#This Row],[Import Duties]]),2) -> 7.3 | O5: 0 | P5: 1 | Q5: 0 | R5: =ROUNDUP(Main[[#This Row],[Transport2]]/Main[[#This Row],[Cantidad_Min]],2) -> 36.12 | S5: =_xlfn.XLOOKUP(Main[[#This Row],[Type of Box]], Cajas[Nombre], Cajas[Largo]) -> 105 | T5: =_xlfn.XLOOKUP(Main[[#This Row],[Type of Box]], Cajas[Nombre], Cajas[Ancho]) -> 17 | U5: =_xlfn.XLOOKUP(Main[[#This Row],[Type of Box]], Cajas[Nombre], Cajas[Alto]) -> 17 | V5: =IF(Main[[#This Row],[Type of Box]]="", "", IF(OR(Main[[#This Row],[Type of Box]]="QB", Main[[#This Row],[Type of Box]]="EB", Main[[#This Row],[Type of Box]]="HB", Main[[#This Row],[Type of Box]]="QB2", Main[[#This Row],[Type of Box]]="EB2", Main[[#This Row],[Type of Box]]="SB"), (Main[[#This Row],[Largo2]]*Main[[#This Row],[Ancho]]*Main[[#This Row],[Alto]])/6000, ((Main[[#This Row],[Largo2]]+Sheet1!$U$2)*(Main[[#This Row],[Ancho]]+Sheet1!$U$2)*(Main[[#This Row],[Alto]]+Sheet1!$U$2))/6000)) -> 5.0575 | W5: =ROUNDUP(((Main[[#This Row],[Volumen]]*5.25))*1.36,2) -> 36.12 | X5: 0.1586 | Y5: =Main[[#This Row],[Cantidad_Min]]*Main[[#This Row],[Precio]]*Main[[#This Row],[Qty]] -> 259.97849 | Z5: =_xlfn.XLOOKUP(Main[[#This Row],[Finca]], Fincas[Nombre], Fincas[ID]) -> 77 | AA5: {=_xlfn.LET( _xlpm.txt, Main[[#This Row],[Standing Orders]], _xlpm.q2num, IFERROR(VALUE(Guias!$M$2), ""), _xlpm.q2txt, UPPER(Guias!$M$2), _xlpm.weekIsOdd, IF(_xlpm.q2num<>"", MOD(_xlpm.q2num,2)=1, IF(ISNUMBER(FIND("IMPAR", _xlpm.q2txt)), TRUE, IF(ISNUMBER(FIND("PAR", _xlpm.q2txt)), FALSE, TRUE))), _xlpm.parts, IF(TRIM(_xlpm.txt)="", "", _xlfn.TOCOL(_xlfn.TEXTSPLIT(SUBSTITUTE(_xlpm.txt, CHAR(160), " "), ";"), 1)), _xlpm.build, IF(_xlfn.VALUETOTEXT(_xlpm.parts)="", "", _xlfn.MAP(_xlpm.parts, _xlfn.LAMBDA(_xlpm.r, _xlfn.LET( _xlpm.s, TRIM(_xlpm.r), _xlpm.s_upper, UPPER(_xlpm.s), _xlpm.p_marker, IF(ISNUMBER(FIND("(*IMPAR)", _xlpm.s_upper)), "impar", IF(ISNUMBER(FIND("(*PAR)", _xlpm.s_upper)), "par", "")), _xlpm.allow, IF(_xlpm.p_marker="", TRUE, IF(_xlpm.p_marker="impar", _xlpm.weekIsOdd, NOT(_xlpm.weekIsOdd))), IF(NOT(_xlpm.allow), "", _xlfn.LET( _xlpm.num, IFERROR(VALUE(LEFT(_xlpm.s, FIND(" ", _xlpm.s & " ")-1)), 0), _xlpm.rawname, TRIM(IFERROR(_xlfn.TEXTAFTER(_xlpm.s, " "), "")), _xlpm.name_pre, IFERROR(_xlfn.TEXTBEFORE(_xlpm.rawname, "["), _xlpm.rawname), _xlpm.name, TRIM(IFERROR(_xlfn.TEXTBEFORE(_xlpm.name_pre, "("), _xlpm.name_pre)), _xlpm.id, _xlfn.XLOOKUP(_xlpm.name, Vendedores[Fragmento], Vendedores[ID], ""), IF(OR(_xlpm.id="", _xlpm.num<=0), "", LEFT(REPT(_xlpm.id & ",", _xlpm.num), LEN(REPT(_xlpm.id & ",", _xlpm.num)) - 1)) ) ) ) ))), _xlpm.resultado, _xlfn.TEXTJOIN(",", TRUE, _xlpm.build), IF(_xlpm.resultado="", "", _xlpm.resultado & ",") )} | AB5: Y | AC5: Natalias Mix
A6: Agrogana | B6: 2 | C6: EB | D6: 1 | E6: 1 | F6: Royal Mix | G6: ="Sweet Pea/Gerbs/Satice/Anemones/Ranunc/Delph/Veronicas/Limonium x 120 " & _xlfn.XLOOKUP(Main[[#This Row],[FechaEntrega]], Guias[Fecha], Guias[Llegada]) -> Sweet Pea/Gerbs/Satice/Anemones/Ranunc/Delph/Veronicas/Limonium x 120 (T/W) | H6: PO107158 | I6: 53.3 | J6: =_xlfn.LET( _xlpm.result, 1-((Main[[#This Row],[Cost]]+Main[[#This Row],[Duties]]+Main[[#This Row],[Transport]])/((Main[[#This Row],[Precio]]*0.96))), IF(_xlpm.result<0, "BAJO", IF(_xlpm.result>1, "ALTO", _xlpm.result)) ) -> 0.32023246 | K6: 149.99 | L6: {=_xlfn.LET( _xlpm.DiaSemana, WEEKDAY(Main[[#This Row],[FechaEntrega]], 2), _xlpm.CajaEcuador, OR(Main[[#This Row],[Type of Box]]="QB", Main[[#This Row],[Type of Box]]="EB", Main[[#This Row],[Type of Box]]="HB", Main[[#This Row],[Type of Box]]="SB"), _xlpm.CajaColombia, OR(Main[[#This Row],[Type of Box]]="QB2", Main[[#This Row],[Type of Box]]="EB2"), _xlpm.EsTF, ISNUMBER(SEARCH("T/F", Main[[#This Row],[Nombre]])), _xlpm.FincaCol, OR(Main[[#This Row],[Finca]]="Plazoleta", Main[[#This Row],[Finca]]="Flowers Party", Main[[#This Row],[Finca]]="HydranFlowers", Main[[#This Row],[Finca]]="Alexandra Farms", Main[[#This Row],[Finca]]="Circasia S.A.S.", Main[[#This Row],[Finca]]="Vuelven S.A.S.", Main[[#This Row],[Finca]]="Cultivos del Norte", Main[[#This Row],[Finca]]="La Conchita"), _xlpm.DiaGuia, _xlfn.IFS( AND(_xlpm.DiaSemana=1, _xlpm.CajaEcuador), "Lunes", AND(_xlpm.DiaSemana=1, _xlpm.CajaColombia), "Lunes", AND(_xlpm.DiaSemana=2, _xlpm.CajaEcuador), "Martes", AND(_xlpm.DiaSemana=2, _xlpm.CajaColombia), "Lunes", _xlpm.DiaSemana=3, "Miercoles", AND(_xlpm.DiaSemana=4, _xlpm.CajaEcuador), "Jueves", AND(_xlpm.DiaSemana=4, _xlpm.CajaColombia), "Miercoles", AND(_xlpm.DiaSemana=5, _xlpm.CajaEcuador), "Viernes", AND(_xlpm.DiaSemana=5, _xlpm.CajaColombia), "Jueves", AND(_xlpm.DiaSemana=6, _xlpm.CajaEcuador, _xlpm.EsTF), "Sabado B", AND(_xlpm.DiaSemana=6, _xlpm.CajaEcuador), "Viernes", AND(_xlpm.DiaSemana=6, _xlpm.CajaColombia), "Viernes", TRUE, "" ), _xlpm.ColGuia, _xlfn.IFS( _xlpm.DiaSemana=3, Guias[Ecuador], _xlpm.CajaColombia, Guias[Colombia], TRUE, Guias[Ecuador] ), _xlpm.VuelosError, IFERROR(_xlfn.XLOOKUP(_xlpm.DiaGuia, Guias[Día], Guias[Vuelos])="***Error de Fecha***", FALSE), _xlpm.SemanaIncorrecta, _xlfn.ISOWEEKNUM(Main[[#This Row],[FechaEntrega]]-2) <> Guias!$M$2, IF(_xlpm.SemanaIncorrecta, "ERROR S", IF(ISNA(MATCH(Main[[#This Row],[FechaEntrega]], Guias[Fecha], 0)), "ERROR F", IF(_xlfn.XOR(_xlpm.FincaCol, _xlpm.CajaColombia), "ERROR P", IF(_xlpm.DiaGuia="", "", IF(_xlpm.VuelosError, "ERROR V", _xlfn.XLOOKUP(_xlpm.DiaGuia, Guias[Día], _xlpm.ColGuia) ) ) ) ) ) )} -> 16977 | M6: =Guias!$B$3 -> 46310 | N6: =ROUNDUP((Main[[#This Row],[Cost]]*Main[[#This Row],[Import Duties]]),2) -> 8.46 | O6: 0 | P6: 1 | Q6: 0 | R6: =ROUNDUP(Main[[#This Row],[Transport2]]/Main[[#This Row],[Cantidad_Min]],2) -> 36.12 | S6: =_xlfn.XLOOKUP(Main[[#This Row],[Type of Box]], Cajas[Nombre], Cajas[Largo]) -> 105 | T6: =_xlfn.XLOOKUP(Main[[#This Row],[Type of Box]], Cajas[Nombre], Cajas[Ancho]) -> 17 | U6: =_xlfn.XLOOKUP(Main[[#This Row],[Type of Box]], Cajas[Nombre], Cajas[Alto]) -> 17 | V6: =IF(Main[[#This Row],[Type of Box]]="", "", IF(OR(Main[[#This Row],[Type of Box]]="QB", Main[[#This Row],[Type of Box]]="EB", Main[[#This Row],[Type of Box]]="HB", Main[[#This Row],[Type of Box]]="QB2", Main[[#This Row],[Type of Box]]="EB2", Main[[#This Row],[Type of Box]]="SB"), (Main[[#This Row],[Largo2]]*Main[[#This Row],[Ancho]]*Main[[#This Row],[Alto]])/6000, ((Main[[#This Row],[Largo2]]+Sheet1!$U$2)*(Main[[#This Row],[Ancho]]+Sheet1!$U$2)*(Main[[#This Row],[Alto]]+Sheet1!$U$2))/6000)) -> 5.0575 | W6: =ROUNDUP(((Main[[#This Row],[Volumen]]*5.25))*1.36,2) -> 36.12 | X6: 0.1586 | Y6: =Main[[#This Row],[Cantidad_Min]]*Main[[#This Row],[Precio]]*Main[[#This Row],[Qty]] -> 299.98 | Z6: =_xlfn.XLOOKUP(Main[[#This Row],[Finca]], Fincas[Nombre], Fincas[ID]) -> 77 | AA6: {=_xlfn.LET( _xlpm.txt, Main[[#This Row],[Standing Orders]], _xlpm.q2num, IFERROR(VALUE(Guias!$M$2), ""), _xlpm.q2txt, UPPER(Guias!$M$2), _xlpm.weekIsOdd, IF(_xlpm.q2num<>"", MOD(_xlpm.q2num,2)=1, IF(ISNUMBER(FIND("IMPAR", _xlpm.q2txt)), TRUE, IF(ISNUMBER(FIND("PAR", _xlpm.q2txt)), FALSE, TRUE))), _xlpm.parts, IF(TRIM(_xlpm.txt)="", "", _xlfn.TOCOL(_xlfn.TEXTSPLIT(SUBSTITUTE(_xlpm.txt, CHAR(160), " "), ";"), 1)), _xlpm.build, IF(_xlfn.VALUETOTEXT(_xlpm.parts)="", "", _xlfn.MAP(_xlpm.parts, _xlfn.LAMBDA(_xlpm.r, _xlfn.LET( _xlpm.s, TRIM(_xlpm.r), _xlpm.s_upper, UPPER(_xlpm.s), _xlpm.p_marker, IF(ISNUMBER(FIND("(*IMPAR)", _xlpm.s_upper)), "impar", IF(ISNUMBER(FIND("(*PAR)", _xlpm.s_upper)), "par", "")), _xlpm.allow, IF(_xlpm.p_marker="", TRUE, IF(_xlpm.p_marker="impar", _xlpm.weekIsOdd, NOT(_xlpm.weekIsOdd))), IF(NOT(_xlpm.allow), "", _xlfn.LET( _xlpm.num, IFERROR(VALUE(LEFT(_xlpm.s, FIND(" ", _xlpm.s & " ")-1)), 0), _xlpm.rawname, TRIM(IFERROR(_xlfn.TEXTAFTER(_xlpm.s, " "), "")), _xlpm.name_pre, IFERROR(_xlfn.TEXTBEFORE(_xlpm.rawname, "["), _xlpm.rawname), _xlpm.name, TRIM(IFERROR(_xlfn.TEXTBEFORE(_xlpm.name_pre, "("), _xlpm.name_pre)), _xlpm.id, _xlfn.XLOOKUP(_xlpm.name, Vendedores[Fragmento], Vendedores[ID], ""), IF(OR(_xlpm.id="", _xlpm.num<=0), "", LEFT(REPT(_xlpm.id & ",", _xlpm.num), LEN(REPT(_xlpm.id & ",", _xlpm.num)) - 1)) ) ) ) ))), _xlpm.resultado, _xlfn.TEXTJOIN(",", TRUE, _xlpm.build), IF(_xlpm.resultado="", "", _xlpm.resultado & ",") )} | AB6: Y | AC6: Summer Vibes
A7: Agrogana | B7: 1 | C7: EB | D7: 1 | E7: 1 | F7: Florist Mix | G7: ="20 Scoop/20 Freesias/20 Rumex/20 Campanullas/20 Veronicas/20 Marigold x 120 " & _xlfn.XLOOKUP(Main[[#This Row],[FechaEntrega]], Guias[Fecha], Guias[Llegada]) -> 20 Scoop/20 Freesias/20 Rumex/20 Campanullas/20 Veronicas/20 Marigold x 120 (T/W) | H7: PO107159 | I7: 63 | J7: =_xlfn.LET( _xlpm.result, 1-((Main[[#This Row],[Cost]]+Main[[#This Row],[Duties]]+Main[[#This Row],[Transport]])/((Main[[#This Row],[Precio]]*0.96))), IF(_xlpm.result<0, "BAJO", IF(_xlpm.result>1, "ALTO", _xlpm.result)) ) -> 0.28953893 | K7: 159.99 | L7: {=_xlfn.LET( _xlpm.DiaSemana, WEEKDAY(Main[[#This Row],[FechaEntrega]], 2), _xlpm.CajaEcuador, OR(Main[[#This Row],[Type of Box]]="QB", Main[[#This Row],[Type of Box]]="EB", Main[[#This Row],[Type of Box]]="HB", Main[[#This Row],[Type of Box]]="SB"), _xlpm.CajaColombia, OR(Main[[#This Row],[Type of Box]]="QB2", Main[[#This Row],[Type of Box]]="EB2"), _xlpm.EsTF, ISNUMBER(SEARCH("T/F", Main[[#This Row],[Nombre]])), _xlpm.FincaCol, OR(Main[[#This Row],[Finca]]="Plazoleta", Main[[#This Row],[Finca]]="Flowers Party", Main[[#This Row],[Finca]]="HydranFlowers", Main[[#This Row],[Finca]]="Alexandra Farms", Main[[#This Row],[Finca]]="Circasia S.A.S.", Main[[#This Row],[Finca]]="Vuelven S.A.S.", Main[[#This Row],[Finca]]="Cultivos del Norte", Main[[#This Row],[Finca]]="La Conchita"), _xlpm.DiaGuia, _xlfn.IFS( AND(_xlpm.DiaSemana=1, _xlpm.CajaEcuador), "Lunes", AND(_xlpm.DiaSemana=1, _xlpm.CajaColombia), "Lunes", AND(_xlpm.DiaSemana=2, _xlpm.CajaEcuador), "Martes", AND(_xlpm.DiaSemana=2, _xlpm.CajaColombia), "Lunes", _xlpm.DiaSemana=3, "Miercoles", AND(_xlpm.DiaSemana=4, _xlpm.CajaEcuador), "Jueves", AND(_xlpm.DiaSemana=4, _xlpm.CajaColombia), "Miercoles", AND(_xlpm.DiaSemana=5, _xlpm.CajaEcuador), "Viernes", AND(_xlpm.DiaSemana=5, _xlpm.CajaColombia), "Jueves", AND(_xlpm.DiaSemana=6, _xlpm.CajaEcuador, _xlpm.EsTF), "Sabado B", AND(_xlpm.DiaSemana=6, _xlpm.CajaEcuador), "Viernes", AND(_xlpm.DiaSemana=6, _xlpm.CajaColombia), "Viernes", TRUE, "" ), _xlpm.ColGuia, _xlfn.IFS( _xlpm.DiaSemana=3, Guias[Ecuador], _xlpm.CajaColombia, Guias[Colombia], TRUE, Guias[Ecuador] ), _xlpm.VuelosError, IFERROR(_xlfn.XLOOKUP(_xlpm.DiaGuia, Guias[Día], Guias[Vuelos])="***Error de Fecha***", FALSE), _xlpm.SemanaIncorrecta, _xlfn.ISOWEEKNUM(Main[[#This Row],[FechaEntrega]]-2) <> Guias!$M$2, IF(_xlpm.SemanaIncorrecta, "ERROR S", IF(ISNA(MATCH(Main[[#This Row],[FechaEntrega]], Guias[Fecha], 0)), "ERROR F", IF(_xlfn.XOR(_xlpm.FincaCol, _xlpm.CajaColombia), "ERROR P", IF(_xlpm.DiaGuia="", "", IF(_xlpm.VuelosError, "ERROR V", _xlfn.XLOOKUP(_xlpm.DiaGuia, Guias[Día], _xlpm.ColGuia) ) ) ) ) ) )} -> 16977 | M7: =Guias!$B$3 -> 46310 | N7: =ROUNDUP((Main[[#This Row],[Cost]]*Main[[#This Row],[Import Duties]]),2) -> 10 | O7: 0 | P7: 1 | Q7: 0 | R7: =ROUNDUP(Main[[#This Row],[Transport2]]/Main[[#This Row],[Cantidad_Min]],2) -> 36.12 | S7: =_xlfn.XLOOKUP(Main[[#This Row],[Type of Box]], Cajas[Nombre], Cajas[Largo]) -> 105 | T7: =_xlfn.XLOOKUP(Main[[#This Row],[Type of Box]], Cajas[Nombre], Cajas[Ancho]) -> 17 | U7: =_xlfn.XLOOKUP(Main[[#This Row],[Type of Box]], Cajas[Nombre], Cajas[Alto]) -> 17 | V7: =IF(Main[[#This Row],[Type of Box]]="", "", IF(OR(Main[[#This Row],[Type of Box]]="QB", Main[[#This Row],[Type of Box]]="EB", Main[[#This Row],[Type of Box]]="HB", Main[[#This Row],[Type of Box]]="QB2", Main[[#This Row],[Type of Box]]="EB2", Main[[#This Row],[Type of Box]]="SB"), (Main[[#This Row],[Largo2]]*Main[[#This Row],[Ancho]]*Main[[#This Row],[Alto]])/6000, ((Main[[#This Row],[Largo2]]+Sheet1!$U$2)*(Main[[#This Row],[Ancho]]+Sheet1!$U$2)*(Main[[#This Row],[Alto]]+Sheet1!$U$2))/6000)) -> 5.0575 | W7: =ROUNDUP(((Main[[#This Row],[Volumen]]*5.25))*1.36,2) -> 36.12 | X7: 0.1586 | Y7: =Main[[#This Row],[Cantidad_Min]]*Main[[#This Row],[Precio]]*Main[[#This Row],[Qty]] -> 159.99 | Z7: =_xlfn.XLOOKUP(Main[[#This Row],[Finca]], Fincas[Nombre], Fincas[ID]) -> 77 | AA7: {=_xlfn.LET( _xlpm.txt, Main[[#This Row],[Standing Orders]], _xlpm.q2num, IFERROR(VALUE(Guias!$M$2), ""), _xlpm.q2txt, UPPER(Guias!$M$2), _xlpm.weekIsOdd, IF(_xlpm.q2num<>"", MOD(_xlpm.q2num,2)=1, IF(ISNUMBER(FIND("IMPAR", _xlpm.q2txt)), TRUE, IF(ISNUMBER(FIND("PAR", _xlpm.q2txt)), FALSE, TRUE))), _xlpm.parts, IF(TRIM(_xlpm.txt)="", "", _xlfn.TOCOL(_xlfn.TEXTSPLIT(SUBSTITUTE(_xlpm.txt, CHAR(160), " "), ";"), 1)), _xlpm.build, IF(_xlfn.VALUETOTEXT(_xlpm.parts)="", "", _xlfn.MAP(_xlpm.parts, _xlfn.LAMBDA(_xlpm.r, _xlfn.LET( _xlpm.s, TRIM(_xlpm.r), _xlpm.s_upper, UPPER(_xlpm.s), _xlpm.p_marker, IF(ISNUMBER(FIND("(*IMPAR)", _xlpm.s_upper)), "impar", IF(ISNUMBER(FIND("(*PAR)", _xlpm.s_upper)), "par", "")), _xlpm.allow, IF(_xlpm.p_marker="", TRUE, IF(_xlpm.p_marker="impar", _xlpm.weekIsOdd, NOT(_xlpm.weekIsOdd))), IF(NOT(_xlpm.allow), "", _xlfn.LET( _xlpm.num, IFERROR(VALUE(LEFT(_xlpm.s, FIND(" ", _xlpm.s & " ")-1)), 0), _xlpm.rawname, TRIM(IFERROR(_xlfn.TEXTAFTER(_xlpm.s, " "), "")), _xlpm.name_pre, IFERROR(_xlfn.TEXTBEFORE(_xlpm.rawname, "["), _xlpm.rawname), _xlpm.name, TRIM(IFERROR(_xlfn.TEXTBEFORE(_xlpm.name_pre, "("), _xlpm.name_pre)), _xlpm.id, _xlfn.XLOOKUP(_xlpm.name, Vendedores[Fragmento], Vendedores[ID], ""), IF(OR(_xlpm.id="", _xlpm.num<=0), "", LEFT(REPT(_xlpm.id & ",", _xlpm.num), LEN(REPT(_xlpm.id & ",", _xlpm.num)) - 1)) ) ) ) ))), _xlpm.resultado, _xlfn.TEXTJOIN(",", TRUE, _xlpm.build), IF(_xlpm.resultado="", "", _xlpm.resultado & ",") )} | AB7: Y
A8: Agroprim | B8: 1 | C8: EB | D8: 35 | E8: 35 | F8: Sunflower Select | G8: ="Vincents Choice " & _xlfn.XLOOKUP(Main[[#This Row],[FechaEntrega]], Guias[Fecha], Guias[Llegada]) -> Vincents Choice (W/T) | H8: PO107160 | I8: 0.3 | J8: =_xlfn.LET( _xlpm.result, 1-((Main[[#This Row],[Cost]]+Main[[#This Row],[Duties]]+Main[[#This Row],[Transport]])/((Main[[#This Row],[Precio]]*0.96))), IF(_xlpm.result<0, "BAJO", IF(_xlpm.result>1, "ALTO", _xlpm.result)) ) -> 0.17261905 | K8: 1.75 | L8: {=_xlfn.LET( _xlpm.DiaSemana, WEEKDAY(Main[[#This Row],[FechaEntrega]], 2), _xlpm.CajaEcuador, OR(Main[[#This Row],[Type of Box]]="QB", Main[[#This Row],[Type of Box]]="EB", Main[[#This Row],[Type of Box]]="HB", Main[[#This Row],[Type of Box]]="SB"), _xlpm.CajaColombia, OR(Main[[#This Row],[Type of Box]]="QB2", Main[[#This Row],[Type of Box]]="EB2"), _xlpm.EsTF, ISNUMBER(SEARCH("T/F", Main[[#This Row],[Nombre]])), _xlpm.FincaCol, OR(Main[[#This Row],[Finca]]="Plazoleta", Main[[#This Row],[Finca]]="Flowers Party", Main[[#This Row],[Finca]]="HydranFlowers", Main[[#This Row],[Finca]]="Alexandra Farms", Main[[#This Row],[Finca]]="Circasia S.A.S.", Main[[#This Row],[Finca]]="Vuelven S.A.S.", Main[[#This Row],[Finca]]="Cultivos del Norte", Main[[#This Row],[Finca]]="La Conchita"), _xlpm.DiaGuia, _xlfn.IFS( AND(_xlpm.DiaSemana=1, _xlpm.CajaEcuador), "Lunes", AND(_xlpm.DiaSemana=1, _xlpm.CajaColombia), "Lunes", AND(_xlpm.DiaSemana=2, _xlpm.CajaEcuador), "Martes", AND(_xlpm.DiaSemana=2, _xlpm.CajaColombia), "Lunes", _xlpm.DiaSemana=3, "Miercoles", AND(_xlpm.DiaSemana=4, _xlpm.CajaEcuador), "Jueves", AND(_xlpm.DiaSemana=4, _xlpm.CajaColombia), "Miercoles", AND(_xlpm.DiaSemana=5, _xlpm.CajaEcuador), "Viernes", AND(_xlpm.DiaSemana=5, _xlpm.CajaColombia), "Jueves", AND(_xlpm.DiaSemana=6, _xlpm.CajaEcuador, _xlpm.EsTF), "Sabado B", AND(_xlpm.DiaSemana=6, _xlpm.CajaEcuador), "Viernes", AND(_xlpm.DiaSemana=6, _xlpm.CajaColombia), "Viernes", TRUE, "" ), _xlpm.ColGuia, _xlfn.IFS( _xlpm.DiaSemana=3, Guias[Ecuador], _xlpm.CajaColombia, Guias[Colombia], TRUE, Guias[Ecuador] ), _xlpm.VuelosError, IFERROR(_xlfn.XLOOKUP(_xlpm.DiaGuia, Guias[Día], Guias[Vuelos])="***Error de Fecha***", FALSE), _xlpm.SemanaIncorrecta, _xlfn.ISOWEEKNUM(Main[[#This Row],[FechaEntrega]]-2) <> Guias!$M$2, IF(_xlpm.SemanaIncorrecta, "ERROR S", IF(ISNA(MATCH(Main[[#This Row],[FechaEntrega]], Guias[Fecha], 0)), "ERROR F", IF(_xlfn.XOR(_xlpm.FincaCol, _xlpm.CajaColombia), "ERROR P", IF(_xlpm.DiaGuia="", "", IF(_xlpm.VuelosError, "ERROR V", _xlfn.XLOOKUP(_xlpm.DiaGuia, Guias[Día], _xlpm.ColGuia) ) ) ) ) ) )} -> 16979 | M8: =Guias!$B$4 -> 46311 | N8: =ROUNDUP((Main[[#This Row],[Cost]]*Main[[#This Row],[Import Duties]]),2) -> 0.05 | O8: 0 | P8: 1 | Q8: 0 | R8: =ROUNDUP(Main[[#This Row],[Transport2]]/Main[[#This Row],[Cantidad_Min]],2) -> 1.04 | S8: =_xlfn.XLOOKUP(Main[[#This Row],[Type of Box]], Cajas[Nombre], Cajas[Largo]) -> 105 | T8: =_xlfn.XLOOKUP(Main[[#This Row],[Type of Box]], Cajas[Nombre], Cajas[Ancho]) -> 17 | U8: =_xlfn.XLOOKUP(Main[[#This Row],[Type of Box]], Cajas[Nombre], Cajas[Alto]) -> 17 | V8: =IF(Main[[#This Row],[Type of Box]]="", "", IF(OR(Main[[#This Row],[Type of Box]]="QB", Main[[#This Row],[Type of Box]]="EB", Main[[#This Row],[Type of Box]]="HB", Main[[#This Row],[Type of Box]]="QB2", Main[[#This Row],[Type of Box]]="EB2", Main[[#This Row],[Type of Box]]="SB"), (Main[[#This Row],[Largo2]]*Main[[#This Row],[Ancho]]*Main[[#This Row],[Alto]])/6000, ((Main[[#This Row],[Largo2]]+Sheet1!$U$2)*(Main[[#This Row],[Ancho]]+Sheet1!$U$2)*(Main[[#This Row],[Alto]]+Sheet1!$U$2))/6000)) -> 5.0575 | W8: =ROUNDUP(((Main[[#This Row],[Volumen]]*5.25))*1.36,2) -> 36.12 | X8: 0.1586 | Y8: =Main[[#This Row],[Cantidad_Min]]*Main[[#This Row],[Precio]]*Main[[#This Row],[Qty]] -> 61.25 | Z8: =_xlfn.XLOOKUP(Main[[#This Row],[Finca]], Fincas[Nombre], Fincas[ID]) -> 6 | AA8: {=_xlfn.LET( _xlpm.txt, Main[[#This Row],[Standing Orders]], _xlpm.q2num, IFERROR(VALUE(Guias!$M$2), ""), _xlpm.q2txt, UPPER(Guias!$M$2), _xlpm.weekIsOdd, IF(_xlpm.q2num<>"", MOD(_xlpm.q2num,2)=1, IF(ISNUMBER(FIND("IMPAR", _xlpm.q2txt)), TRUE, IF(ISNUMBER(FIND("PAR", _xlpm.q2txt)), FALSE, TRUE))), _xlpm.parts, IF(TRIM(_xlpm.txt)="", "", _xlfn.TOCOL(_xlfn.TEXTSPLIT(SUBSTITUTE(_xlpm.txt, CHAR(160), " "), ";"), 1)), _xlpm.build, IF(_xlfn.VALUETOTEXT(_xlpm.parts)="", "", _xlfn.MAP(_xlpm.parts, _xlfn.LAMBDA(_xlpm.r, _xlfn.LET( _xlpm.s, TRIM(_xlpm.r), _xlpm.s_upper, UPPER(_xlpm.s), _xlpm.p_marker, IF(ISNUMBER(FIND("(*IMPAR)", _xlpm.s_upper)), "impar", IF(ISNUMBER(FIND("(*PAR)", _xlpm.s_upper)), "par", "")), _xlpm.allow, IF(_xlpm.p_marker="", TRUE, IF(_xlpm.p_marker="impar", _xlpm.weekIsOdd, NOT(_xlpm.weekIsOdd))), IF(NOT(_xlpm.allow), "", _xlfn.LET( _xlpm.num, IFERROR(VALUE(LEFT(_xlpm.s, FIND(" ", _xlpm.s & " ")-1)), 0), _xlpm.rawname, TRIM(IFERROR(_xlfn.TEXTAFTER(_xlpm.s, " "), "")), _xlpm.name_pre, IFERROR(_xlfn.TEXTBEFORE(_xlpm.rawname, "["), _xlpm.rawname), _xlpm.name, TRIM(IFERROR(_xlfn.TEXTBEFORE(_xlpm.name_pre, "("), _xlpm.name_pre)), _xlpm.id, _xlfn.XLOOKUP(_xlpm.name, Vendedores[Fragmento], Vendedores[ID], ""), IF(OR(_xlpm.id="", _xlpm.num<=0), "", LEFT(REPT(_xlpm.id & ",", _xlpm.num), LEN(REPT(_xlpm.id & ",", _xlpm.num)) - 1)) ) ) ) ))), _xlpm.resultado, _xlfn.TEXTJOIN(",", TRUE, _xlpm.build), IF(_xlpm.resultado="", "", _xlpm.resultado & ",") )} -> rbaquero, | AB8: Y | AD8: 1 Ralph [Flowers by Zsuzsana]
A9: Agroprim | B9: 1 | C9: QB | D9: 65 | E9: 65 | F9: Sunflower Select | G9: ="Vincents Choice " & _xlfn.XLOOKUP(Main[[#This Row],[FechaEntrega]], Guias[Fecha], Guias[Llegada]) -> Vincents Choice (W/T) | H9: PO107161 | I9: 0.3 | J9: =_xlfn.LET( _xlpm.result, 1-((Main[[#This Row],[Cost]]+Main[[#This Row],[Duties]]+Main[[#This Row],[Transport]])/((Main[[#This Row],[Precio]]*0.96))), IF(_xlpm.result<0, "BAJO", IF(_xlpm.result>1, "ALTO", _xlpm.result)) ) -> 0.18452381 | K9: 1.75 | L9: {=_xlfn.LET( _xlpm.DiaSemana, WEEKDAY(Main[[#This Row],[FechaEntrega]], 2), _xlpm.CajaEcuador, OR(Main[[#This Row],[Type of Box]]="QB", Main[[#This Row],[Type of Box]]="EB", Main[[#This Row],[Type of Box]]="HB", Main[[#This Row],[Type of Box]]="SB"), _xlpm.CajaColombia, OR(Main[[#This Row],[Type of Box]]="QB2", Main[[#This Row],[Type of Box]]="EB2"), _xlpm.EsTF, ISNUMBER(SEARCH("T/F", Main[[#This Row],[Nombre]])), _xlpm.FincaCol, OR(Main[[#This Row],[Finca]]="Plazoleta", Main[[#This Row],[Finca]]="Flowers Party", Main[[#This Row],[Finca]]="HydranFlowers", Main[[#This Row],[Finca]]="Alexandra Farms", Main[[#This Row],[Finca]]="Circasia S.A.S.", Main[[#This Row],[Finca]]="Vuelven S.A.S.", Main[[#This Row],[Finca]]="Cultivos del Norte", Main[[#This Row],[Finca]]="La Conchita"), _xlpm.DiaGuia, _xlfn.IFS( AND(_xlpm.DiaSemana=1, _xlpm.CajaEcuador), "Lunes", AND(_xlpm.DiaSemana=1, _xlpm.CajaColombia), "Lunes", AND(_xlpm.DiaSemana=2, _xlpm.CajaEcuador), "Martes", AND(_xlpm.DiaSemana=2, _xlpm.CajaColombia), "Lunes", _xlpm.DiaSemana=3, "Miercoles", AND(_xlpm.DiaSemana=4, _xlpm.CajaEcuador), "Jueves", AND(_xlpm.DiaSemana=4, _xlpm.CajaColombia), "Miercoles", AND(_xlpm.DiaSemana=5, _xlpm.CajaEcuador), "Viernes", AND(_xlpm.DiaSemana=5, _xlpm.CajaColombia), "Jueves", AND(_xlpm.DiaSemana=6, _xlpm.CajaEcuador, _xlpm.EsTF), "Sabado B", AND(_xlpm.DiaSemana=6, _xlpm.CajaEcuador), "Viernes", AND(_xlpm.DiaSemana=6, _xlpm.CajaColombia), "Viernes", TRUE, "" ), _xlpm.ColGuia, _xlfn.IFS( _xlpm.DiaSemana=3, Guias[Ecuador], _xlpm.CajaColombia, Guias[Colombia], TRUE, Guias[Ecuador] ), _xlpm.VuelosError, IFERROR(_xlfn.XLOOKUP(_xlpm.DiaGuia, Guias[Día], Guias[Vuelos])="***Error de Fecha***", FALSE), _xlpm.SemanaIncorrecta, _xlfn.ISOWEEKNUM(Main[[#This Row],[FechaEntrega]]-2) <> Guias!$M$2, IF(_xlpm.SemanaIncorrecta, "ERROR S", IF(ISNA(MATCH(Main[[#This Row],[FechaEntrega]], Guias[Fecha], 0)), "ERROR F", IF(_xlfn.XOR(_xlpm.FincaCol, _xlpm.CajaColombia), "ERROR P", IF(_xlpm.DiaGuia="", "", IF(_xlpm.VuelosError, "ERROR V", _xlfn.XLOOKUP(_xlpm.DiaGuia, Guias[Día], _xlpm.ColGuia) ) ) ) ) ) )} -> 16979 | M9: =Guias!$B$4 -> 46311 | N9: =ROUNDUP((Main[[#This Row],[Cost]]*Main[[#This Row],[Import Duties]]),2) -> 0.05 | O9: 0 | P9: 1 | Q9: 0 | R9: =ROUNDUP(Main[[#This Row],[Transport2]]/Main[[#This Row],[Cantidad_Min]],2) -> 1.02 | S9: =_xlfn.XLOOKUP(Main[[#This Row],[Type of Box]], Cajas[Nombre], Cajas[Largo]) -> 99 | T9: =_xlfn.XLOOKUP(Main[[#This Row],[Type of Box]], Cajas[Nombre], Cajas[Ancho]) -> 35 | U9: =_xlfn.XLOOKUP(Main[[#This Row],[Type of Box]], Cajas[Nombre], Cajas[Alto]) -> 16 | V9: =IF(Main[[#This Row],[Type of Box]]="", "", IF(OR(Main[[#This Row],[Type of Box]]="QB", Main[[#This Row],[Type of Box]]="EB", Main[[#This Row],[Type of Box]]="HB", Main[[#This Row],[Type of Box]]="QB2", Main[[#This Row],[Type of Box]]="EB2", Main[[#This Row],[Type of Box]]="SB"), (Main[[#This Row],[Largo2]]*Main[[#This Row],[Ancho]]*Main[[#This Row],[Alto]])/6000, ((Main[[#This Row],[Largo2]]+Sheet1!$U$2)*(Main[[#This Row],[Ancho]]+Sheet1!$U$2)*(Main[[#This Row],[Alto]]+Sheet1!$U$2))/6000)) -> 9.24 | W9: =ROUNDUP(((Main[[#This Row],[Volumen]]*5.25))*1.36,2) -> 65.98 | X9: 0.1586 | Y9: =Main[[#This Row],[Cantidad_Min]]*Main[[#This Row],[Precio]]*Main[[#This Row],[Qty]] -> 113.75 | Z9: =_xlfn.XLOOKUP(Main[[#This Row],[Finca]], Fincas[Nombre], Fincas[ID]) -> 6 | AA9: {=_xlfn.LET( _xlpm.txt, Main[[#This Row],[Standing Orders]], _xlpm.q2num, IFERROR(VALUE(Guias!$M$2), ""), _xlpm.q2txt, UPPER(Guias!$M$2), _xlpm.weekIsOdd, IF(_xlpm.q2num<>"", MOD(_xlpm.q2num,2)=1, IF(ISNUMBER(FIND("IMPAR", _xlpm.q2txt)), TRUE, IF(ISNUMBER(FIND("PAR", _xlpm.q2txt)), FALSE, TRUE))), _xlpm.parts, IF(TRIM(_xlpm.txt)="", "", _xlfn.TOCOL(_xlfn.TEXTSPLIT(SUBSTITUTE(_xlpm.txt, CHAR(160), " "), ";"), 1)), _xlpm.build, IF(_xlfn.VALUETOTEXT(_xlpm.parts)="", "", _xlfn.MAP(_xlpm.parts, _xlfn.LAMBDA(_xlpm.r, _xlfn.LET( _xlpm.s, TRIM(_xlpm.r), _xlpm.s_upper, UPPER(_xlpm.s), _xlpm.p_marker, IF(ISNUMBER(FIND("(*IMPAR)", _xlpm.s_upper)), "impar", IF(ISNUMBER(FIND("(*PAR)", _xlpm.s_upper)), "par", "")), _xlpm.allow, IF(_xlpm.p_marker="", TRUE, IF(_xlpm.p_marker="impar", _xlpm.weekIsOdd, NOT(_xlpm.weekIsOdd))), IF(NOT(_xlpm.allow), "", _xlfn.LET( _xlpm.num, IFERROR(VALUE(LEFT(_xlpm.s, FIND(" ", _xlpm.s & " ")-1)), 0), _xlpm.rawname, TRIM(IFERROR(_xlfn.TEXTAFTER(_xlpm.s, " "), "")), _xlpm.name_pre, IFERROR(_xlfn.TEXTBEFORE(_xlpm.rawname, "["), _xlpm.rawname), _xlpm.name, TRIM(IFERROR(_xlfn.TEXTBEFORE(_xlpm.name_pre, "("), _xlpm.name_pre)), _xlpm.id, _xlfn.XLOOKUP(_xlpm.name, Vendedores[Fragmento], Vendedores[ID], ""), IF(OR(_xlpm.id="", _xlpm.num<=0), "", LEFT(REPT(_xlpm.id & ",", _xlpm.num), LEN(REPT(_xlpm.id & ",", _xlpm.num)) - 1)) ) ) ) ))), _xlpm.resultado, _xlfn.TEXTJOIN(",", TRUE, _xlpm.build), IF(_xlpm.resultado="", "", _xlpm.resultado & ",") )} -> pbodley, | AB9: Y | AD9: 1 Paul []
A10: Betel Flowers | B10: 1 | C10: EB | D10: 50 | E10: 50 | F10: Pin Cushion 30/35cm | G10: ="Assorted Colors " & _xlfn.XLOOKUP(Main[[#This Row],[FechaEntrega]], Guias[Fecha], Guias[Llegada]) -> Assorted Colors (W/T) | H10: PO107162 | I10: 0.4 | J10: =_xlfn.LET( _xlpm.result, 1-((Main[[#This Row],[Cost]]+Main[[#This Row],[Duties]]+Main[[#This Row],[Transport]])/((Main[[#This Row],[Precio]]*0.96))), IF(_xlpm.result<0, "BAJO", IF(_xlpm.result>1, "ALTO", _xlpm.result)) ) -> 0.25955414 | K10: 1.688172 | L10: {=_xlfn.LET( _xlpm.DiaSemana, WEEKDAY(Main[[#This Row],[FechaEntrega]], 2), _xlpm.CajaEcuador, OR(Main[[#This Row],[Type of Box]]="QB", Main[[#This Row],[Type of Box]]="EB", Main[[#This Row],[Type of Box]]="HB", Main[[#This Row],[Type of Box]]="SB"), _xlpm.CajaColombia, OR(Main[[#This Row],[Type of Box]]="QB2", Main[[#This Row],[Type of Box]]="EB2"), _xlpm.EsTF, ISNUMBER(SEARCH("T/F", Main[[#This Row],[Nombre]])), _xlpm.FincaCol, OR(Main[[#This Row],[Finca]]="Plazoleta", Main[[#This Row],[Finca]]="Flowers Party", Main[[#This Row],[Finca]]="HydranFlowers", Main[[#This Row],[Finca]]="Alexandra Farms", Main[[#This Row],[Finca]]="Circasia S.A.S.", Main[[#This Row],[Finca]]="Vuelven S.A.S.", Main[[#This Row],[Finca]]="Cultivos del Norte", Main[[#This Row],[Finca]]="La Conchita"), _xlpm.DiaGuia, _xlfn.IFS( AND(_xlpm.DiaSemana=1, _xlpm.CajaEcuador), "Lunes", AND(_xlpm.DiaSemana=1, _xlpm.CajaColombia), "Lunes", AND(_xlpm.DiaSemana=2, _xlpm.CajaEcuador), "Martes", AND(_xlpm.DiaSemana=2, _xlpm.CajaColombia), "Lunes", _xlpm.DiaSemana=3, "Miercoles", AND(_xlpm.DiaSemana=4, _xlpm.CajaEcuador), "Jueves", AND(_xlpm.DiaSemana=4, _xlpm.CajaColombia), "Miercoles", AND(_xlpm.DiaSemana=5, _xlpm.CajaEcuador), "Viernes", AND(_xlpm.DiaSemana=5, _xlpm.CajaColombia), "Jueves", AND(_xlpm.DiaSemana=6, _xlpm.CajaEcuador, _xlpm.EsTF), "Sabado B", AND(_xlpm.DiaSemana=6, _xlpm.CajaEcuador), "Viernes", AND(_xlpm.DiaSemana=6, _xlpm.CajaColombia), "Viernes", TRUE, "" ), _xlpm.ColGuia, _xlfn.IFS( _xlpm.DiaSemana=3, Guias[Ecuador], _xlpm.CajaColombia, Guias[Colombia], TRUE, Guias[Ecuador] ), _xlpm.VuelosError, IFERROR(_xlfn.XLOOKUP(_xlpm.DiaGuia, Guias[Día], Guias[Vuelos])="***Error de Fecha***", FALSE), _xlpm.SemanaIncorrecta, _xlfn.ISOWEEKNUM(Main[[#This Row],[FechaEntrega]]-2) <> Guias!$M$2, IF(_xlpm.SemanaIncorrecta, "ERROR S", IF(ISNA(MATCH(Main[[#This Row],[FechaEntrega]], Guias[Fecha], 0)), "ERROR F", IF(_xlfn.XOR(_xlpm.FincaCol, _xlpm.CajaColombia), "ERROR P", IF(_xlpm.DiaGuia="", "", IF(_xlpm.VuelosError, "ERROR V", _xlfn.XLOOKUP(_xlpm.DiaGuia, Guias[Día], _xlpm.ColGuia) ) ) ) ) ) )} -> 16979 | M10: =Guias!$B$4 -> 46311 | N10: =ROUNDUP((Main[[#This Row],[Cost]]*Main[[#This Row],[Import Duties]]),2) -> 0.07 | O10: 0 | P10: 1 | Q10: 0 | R10: =ROUNDUP(Main[[#This Row],[Transport2]]/Main[[#This Row],[Cantidad_Min]],2) -> 0.73 | S10: =_xlfn.XLOOKUP(Main[[#This Row],[Type of Box]], Cajas[Nombre], Cajas[Largo]) -> 105 | T10: =_xlfn.XLOOKUP(Main[[#This Row],[Type of Box]], Cajas[Nombre], Cajas[Ancho]) -> 17 | U10: =_xlfn.XLOOKUP(Main[[#This Row],[Type of Box]], Cajas[Nombre], Cajas[Alto]) -> 17 | V10: =IF(Main[[#This Row],[Type of Box]]="", "", IF(OR(Main[[#This Row],[Type of Box]]="QB", Main[[#This Row],[Type of Box]]="EB", Main[[#This Row],[Type of Box]]="HB", Main[[#This Row],[Type of Box]]="QB2", Main[[#This Row],[Type of Box]]="EB2", Main[[#This Row],[Type of Box]]="SB"), (Main[[#This Row],[Largo2]]*Main[[#This Row],[Ancho]]*Main[[#This Row],[Alto]])/6000, ((Main[[#This Row],[Largo2]]+Sheet1!$U$2)*(Main[[#This Row],[Ancho]]+Sheet1!$U$2)*(Main[[#This Row],[Alto]]+Sheet1!$U$2))/6000)) -> 5.0575 | W10: =ROUNDUP(((Main[[#This Row],[Volumen]]*5.25))*1.36,2) -> 36.12 | X10: 0.1586 | Y10: =Main[[#This Row],[Cantidad_Min]]*Main[[#This Row],[Precio]]*Main[[#This Row],[Qty]] -> 84.408602 | Z10: =_xlfn.XLOOKUP(Main[[#This Row],[Finca]], Fincas[Nombre], Fincas[ID]) -> 51 | AA10: {=_xlfn.LET( _xlpm.txt, Main[[#This Row],[Standing Orders]], _xlpm.q2num, IFERROR(VALUE(Guias!$M$2), ""), _xlpm.q2txt, UPPER(Guias!$M$2), _xlpm.weekIsOdd, IF(_xlpm.q2num<>"", MOD(_xlpm.q2num,2)=1, IF(ISNUMBER(FIND("IMPAR", _xlpm.q2txt)), TRUE, IF(ISNUMBER(FIND("PAR", _xlpm.q2txt)), FALSE, TRUE))), _xlpm.parts, IF(TRIM(_xlpm.txt)="", "", _xlfn.TOCOL(_xlfn.TEXTSPLIT(SUBSTITUTE(_xlpm.txt, CHAR(160), " "), ";"), 1)), _xlpm.build, IF(_xlfn.VALUETOTEXT(_xlpm.parts)="", "", _xlfn.MAP(_xlpm.parts, _xlfn.LAMBDA(_xlpm.r, _xlfn.LET( _xlpm.s, TRIM(_xlpm.r), _xlpm.s_upper, UPPER(_xlpm.s), _xlpm.p_marker, IF(ISNUMBER(FIND("(*IMPAR)", _xlpm.s_upper)), "impar", IF(ISNUMBER(FIND("(*PAR)", _xlpm.s_upper)), "par", "")), _xlpm.allow, IF(_xlpm.p_marker="", TRUE, IF(_xlpm.p_marker="impar", _xlpm.weekIsOdd, NOT(_xlpm.weekIsOdd))), IF(NOT(_xlpm.allow), "", _xlfn.LET( _xlpm.num, IFERROR(VALUE(LEFT(_xlpm.s, FIND(" ", _xlpm.s & " ")-1)), 0), _xlpm.rawname, TRIM(IFERROR(_xlfn.TEXTAFTER(_xlpm.s, " "), "")), _xlpm.name_pre, IFERROR(_xlfn.TEXTBEFORE(_xlpm.rawname, "["), _xlpm.rawname), _xlpm.name, TRIM(IFERROR(_xlfn.TEXTBEFORE(_xlpm.name_pre, "("), _xlpm.name_pre)), _xlpm.id, _xlfn.XLOOKUP(_xlpm.name, Vendedores[Fragmento], Vendedores[ID], ""), IF(OR(_xlpm.id="", _xlpm.num<=0), "", LEFT(REPT(_xlpm.id & ",", _xlpm.num), LEN(REPT(_xlpm.id & ",", _xlpm.num)) - 1)) ) ) ) ))), _xlpm.resultado, _xlfn.TEXTJOIN(",", TRUE, _xlpm.build), IF(_xlpm.resultado="", "", _xlpm.resultado & ",") )} -> rbaquero, | AB10: Y | AD10: 1 Ralph (*Par) [Wine & Blooms]
A11: Betel Flowers | B11: 1 | C11: EB | D11: 50 | E11: 50 | F11: Pin Cushion 30/35cm | G11: ="Assorted Colors " & _xlfn.XLOOKUP(Main[[#This Row],[FechaEntrega]], Guias[Fecha], Guias[Llegada]) -> Assorted Colors (W/T) | H11: PO107163 | I11: 0.4 | J11: =_xlfn.LET( _xlpm.result, 1-((Main[[#This Row],[Cost]]+Main[[#This Row],[Duties]]+Main[[#This Row],[Transport]])/((Main[[#This Row],[Precio]]*0.96))), IF(_xlpm.result<0, "BAJO", IF(_xlpm.result>1, "ALTO", _xlpm.result)) ) -> 0.25955414 | K11: 1.688172 | L11: {=_xlfn.LET( _xlpm.DiaSemana, WEEKDAY(Main[[#This Row],[FechaEntrega]], 2), _xlpm.CajaEcuador, OR(Main[[#This Row],[Type of Box]]="QB", Main[[#This Row],[Type of Box]]="EB", Main[[#This Row],[Type of Box]]="HB", Main[[#This Row],[Type of Box]]="SB"), _xlpm.CajaColombia, OR(Main[[#This Row],[Type of Box]]="QB2", Main[[#This Row],[Type of Box]]="EB2"), _xlpm.EsTF, ISNUMBER(SEARCH("T/F", Main[[#This Row],[Nombre]])), _xlpm.FincaCol, OR(Main[[#This Row],[Finca]]="Plazoleta", Main[[#This Row],[Finca]]="Flowers Party", Main[[#This Row],[Finca]]="HydranFlowers", Main[[#This Row],[Finca]]="Alexandra Farms", Main[[#This Row],[Finca]]="Circasia S.A.S.", Main[[#This Row],[Finca]]="Vuelven S.A.S.", Main[[#This Row],[Finca]]="Cultivos del Norte", Main[[#This Row],[Finca]]="La Conchita"), _xlpm.DiaGuia, _xlfn.IFS( AND(_xlpm.DiaSemana=1, _xlpm.CajaEcuador), "Lunes", AND(_xlpm.DiaSemana=1, _xlpm.CajaColombia), "Lunes", AND(_xlpm.DiaSemana=2, _xlpm.CajaEcuador), "Martes", AND(_xlpm.DiaSemana=2, _xlpm.CajaColombia), "Lunes", _xlpm.DiaSemana=3, "Miercoles", AND(_xlpm.DiaSemana=4, _xlpm.CajaEcuador), "Jueves", AND(_xlpm.DiaSemana=4, _xlpm.CajaColombia), "Miercoles", AND(_xlpm.DiaSemana=5, _xlpm.CajaEcuador), "Viernes", AND(_xlpm.DiaSemana=5, _xlpm.CajaColombia), "Jueves", AND(_xlpm.DiaSemana=6, _xlpm.CajaEcuador, _xlpm.EsTF), "Sabado B", AND(_xlpm.DiaSemana=6, _xlpm.CajaEcuador), "Viernes", AND(_xlpm.DiaSemana=6, _xlpm.CajaColombia), "Viernes", TRUE, "" ), _xlpm.ColGuia, _xlfn.IFS( _xlpm.DiaSemana=3, Guias[Ecuador], _xlpm.CajaColombia, Guias[Colombia], TRUE, Guias[Ecuador] ), _xlpm.VuelosError, IFERROR(_xlfn.XLOOKUP(_xlpm.DiaGuia, Guias[Día], Guias[Vuelos])="***Error de Fecha***", FALSE), _xlpm.SemanaIncorrecta, _xlfn.ISOWEEKNUM(Main[[#This Row],[FechaEntrega]]-2) <> Guias!$M$2, IF(_xlpm.SemanaIncorrecta, "ERROR S", IF(ISNA(MATCH(Main[[#This Row],[FechaEntrega]], Guias[Fecha], 0)), "ERROR F", IF(_xlfn.XOR(_xlpm.FincaCol, _xlpm.CajaColombia), "ERROR P", IF(_xlpm.DiaGuia="", "", IF(_xlpm.VuelosError, "ERROR V", _xlfn.XLOOKUP(_xlpm.DiaGuia, Guias[Día], _xlpm.ColGuia) ) ) ) ) ) )} -> 16979 | M11: =Guias!$B$4 -> 46311 | N11: =ROUNDUP((Main[[#This Row],[Cost]]*Main[[#This Row],[Import Duties]]),2) -> 0.07 | O11: 0 | P11: 1 | Q11: 0 | R11: =ROUNDUP(Main[[#This Row],[Transport2]]/Main[[#This Row],[Cantidad_Min]],2) -> 0.73 | S11: =_xlfn.XLOOKUP(Main[[#This Row],[Type of Box]], Cajas[Nombre], Cajas[Largo]) -> 105 | T11: =_xlfn.XLOOKUP(Main[[#This Row],[Type of Box]], Cajas[Nombre], Cajas[Ancho]) -> 17 | U11: =_xlfn.XLOOKUP(Main[[#This Row],[Type of Box]], Cajas[Nombre], Cajas[Alto]) -> 17 | V11: =IF(Main[[#This Row],[Type of Box]]="", "", IF(OR(Main[[#This Row],[Type of Box]]="QB", Main[[#This Row],[Type of Box]]="EB", Main[[#This Row],[Type of Box]]="HB", Main[[#This Row],[Type of Box]]="QB2", Main[[#This Row],[Type of Box]]="EB2", Main[[#This Row],[Type of Box]]="SB"), (Main[[#This Row],[Largo2]]*Main[[#This Row],[Ancho]]*Main[[#This Row],[Alto]])/6000, ((Main[[#This Row],[Largo2]]+Sheet1!$U$2)*(Main[[#This Row],[Ancho]]+Sheet1!$U$2)*(Main[[#This Row],[Alto]]+Sheet1!$U$2))/6000)) -> 5.0575 | W11: =ROUNDUP(((Main[[#This Row],[Volumen]]*5.25))*1.36,2) -> 36.12 | X11: 0.1586 | Y11: =Main[[#This Row],[Cantidad_Min]]*Main[[#This Row],[Precio]]*Main[[#This Row],[Qty]] -> 84.408602 | Z11: =_xlfn.XLOOKUP(Main[[#This Row],[Finca]], Fincas[Nombre], Fincas[ID]) -> 51 | AA11: {=_xlfn.LET( _xlpm.txt, Main[[#This Row],[Standing Orders]], _xlpm.q2num, IFERROR(VALUE(Guias!$M$2), ""), _xlpm.q2txt, UPPER(Guias!$M$2), _xlpm.weekIsOdd, IF(_xlpm.q2num<>"", MOD(_xlpm.q2num,2)=1, IF(ISNUMBER(FIND("IMPAR", _xlpm.q2txt)), TRUE, IF(ISNUMBER(FIND("PAR", _xlpm.q2txt)), FALSE, TRUE))), _xlpm.parts, IF(TRIM(_xlpm.txt)="", "", _xlfn.TOCOL(_xlfn.TEXTSPLIT(SUBSTITUTE(_xlpm.txt, CHAR(160), " "), ";"), 1)), _xlpm.build, IF(_xlfn.VALUETOTEXT(_xlpm.parts)="", "", _xlfn.MAP(_xlpm.parts, _xlfn.LAMBDA(_xlpm.r, _xlfn.LET( _xlpm.s, TRIM(_xlpm.r), _xlpm.s_upper, UPPER(_xlpm.s), _xlpm.p_marker, IF(ISNUMBER(FIND("(*IMPAR)", _xlpm.s_upper)), "impar", IF(ISNUMBER(FIND("(*PAR)", _xlpm.s_upper)), "par", "")), _xlpm.allow, IF(_xlpm.p_marker="", TRUE, IF(_xlpm.p_marker="impar", _xlpm.weekIsOdd, NOT(_xlpm.weekIsOdd))), IF(NOT(_xlpm.allow), "", _xlfn.LET( _xlpm.num, IFERROR(VALUE(LEFT(_xlpm.s, FIND(" ", _xlpm.s & " ")-1)), 0), _xlpm.rawname, TRIM(IFERROR(_xlfn.TEXTAFTER(_xlpm.s, " "), "")), _xlpm.name_pre, IFERROR(_xlfn.TEXTBEFORE(_xlpm.rawname, "["), _xlpm.rawname), _xlpm.name, TRIM(IFERROR(_xlfn.TEXTBEFORE(_xlpm.name_pre, "("), _xlpm.name_pre)), _xlpm.id, _xlfn.XLOOKUP(_xlpm.name, Vendedores[Fragmento], Vendedores[ID], ""), IF(OR(_xlpm.id="", _xlpm.num<=0), "", LEFT(REPT(_xlpm.id & ",", _xlpm.num), LEN(REPT(_xlpm.id & ",", _xlpm.num)) - 1)) ) ) ) ))), _xlpm.resultado, _xlfn.TEXTJOIN(",", TRUE, _xlpm.build), IF(_xlpm.resultado="", "", _xlpm.resultado & ",") )} | AB11: Y
A12: Campos de Aroma | B12: 5 | C12: EB | D12: 40 | E12: 40 | F12: Sunflower Select | G12: Vincents Choice (T/F) | H12: PO107164 | I12: 0.29 | J12: =_xlfn.LET( _xlpm.result, 1-((Main[[#This Row],[Cost]]+Main[[#This Row],[Duties]]+Main[[#This Row],[Transport]])/((Main[[#This Row],[Precio]]*0.96))), IF(_xlpm.result<0, "BAJO", IF(_xlpm.result>1, "ALTO", _xlpm.result)) ) -> 0.22953649 | K12: 1.69 | L12: {=_xlfn.LET( _xlpm.DiaSemana, WEEKDAY(Main[[#This Row],[FechaEntrega]], 2), _xlpm.CajaEcuador, OR(Main[[#This Row],[Type of Box]]="QB", Main[[#This Row],[Type of Box]]="EB", Main[[#This Row],[Type of Box]]="HB", Main[[#This Row],[Type of Box]]="SB"), _xlpm.CajaColombia, OR(Main[[#This Row],[Type of Box]]="QB2", Main[[#This Row],[Type of Box]]="EB2"), _xlpm.EsTF, ISNUMBER(SEARCH("T/F", Main[[#This Row],[Nombre]])), _xlpm.FincaCol, OR(Main[[#This Row],[Finca]]="Plazoleta", Main[[#This Row],[Finca]]="Flowers Party", Main[[#This Row],[Finca]]="HydranFlowers", Main[[#This Row],[Finca]]="Alexandra Farms", Main[[#This Row],[Finca]]="Circasia S.A.S.", Main[[#This Row],[Finca]]="Vuelven S.A.S.", Main[[#This Row],[Finca]]="Cultivos del Norte", Main[[#This Row],[Finca]]="La Conchita"), _xlpm.DiaGuia, _xlfn.IFS( AND(_xlpm.DiaSemana=1, _xlpm.CajaEcuador), "Lunes", AND(_xlpm.DiaSemana=1, _xlpm.CajaColombia), "Lunes", AND(_xlpm.DiaSemana=2, _xlpm.CajaEcuador), "Martes", AND(_xlpm.DiaSemana=2, _xlpm.CajaColombia), "Lunes", _xlpm.DiaSemana=3, "Miercoles", AND(_xlpm.DiaSemana=4, _xlpm.CajaEcuador), "Jueves", AND(_xlpm.DiaSemana=4, _xlpm.CajaColombia), "Miercoles", AND(_xlpm.DiaSemana=5, _xlpm.CajaEcuador), "Viernes", AND(_xlpm.DiaSemana=5, _xlpm.CajaColombia), "Jueves", AND(_xlpm.DiaSemana=6, _xlpm.CajaEcuador, _xlpm.EsTF), "Sabado B", AND(_xlpm.DiaSemana=6, _xlpm.CajaEcuador), "Viernes", AND(_xlpm.DiaSemana=6, _xlpm.CajaColombia), "Viernes", TRUE, "" ), _xlpm.ColGuia, _xlfn.IFS( _xlpm.DiaSemana=3, Guias[Ecuador], _xlpm.CajaColombia, Guias[Colombia], TRUE, Guias[Ecuador] ), _xlpm.VuelosError, IFERROR(_xlfn.XLOOKUP(_xlpm.DiaGuia, Guias[Día], Guias[Vuelos])="***Error de Fecha***", FALSE), _xlpm.SemanaIncorrecta, _xlfn.ISOWEEKNUM(Main[[#This Row],[FechaEntrega]]-2) <> Guias!$M$2, IF(_xlpm.SemanaIncorrecta, "ERROR S", IF(ISNA(MATCH(Main[[#This Row],[FechaEntrega]], Guias[Fecha], 0)), "ERROR F", IF(_xlfn.XOR(_xlpm.FincaCol, _xlpm.CajaColombia), "ERROR P", IF(_xlpm.DiaGuia="", "", IF(_xlpm.VuelosError, "ERROR V", _xlfn.XLOOKUP(_xlpm.DiaGuia, Guias[Día], _xlpm.ColGuia) ) ) ) ) ) )} -> 16952 | M12: =Guias!$B$7 -> 46314 | N12: =ROUNDUP((Main[[#This Row],[Cost]]*Main[[#This Row],[Import Duties]]),2) -> 0.05 | O12: 0 | P12: 1 | Q12: 0 | R12: =ROUNDUP(Main[[#This Row],[Transport2]]/Main[[#This Row],[Cantidad_Min]],2) -> 0.91 | S12: =_xlfn.XLOOKUP(Main[[#This Row],[Type of Box]], Cajas[Nombre], Cajas[Largo]) -> 105 | T12: =_xlfn.XLOOKUP(Main[[#This Row],[Type of Box]], Cajas[Nombre], Cajas[Ancho]) -> 17 | U12: =_xlfn.XLOOKUP(Main[[#This Row],[Type of Box]], Cajas[Nombre], Cajas[Alto]) -> 17 | V12: =IF(Main[[#This Row],[Type of Box]]="", "", IF(OR(Main[[#This Row],[Type of Box]]="QB", Main[[#This Row],[Type of Box]]="EB", Main[[#This Row],[Type of Box]]="HB", Main[[#This Row],[Type of Box]]="QB2", Main[[#This Row],[Type of Box]]="EB2", Main[[#This Row],[Type of Box]]="SB"), (Main[[#This Row],[Largo2]]*Main[[#This Row],[Ancho]]*Main[[#This Row],[Alto]])/6000, ((Main[[#This Row],[Largo2]]+Sheet1!$U$2)*(Main[[#This Row],[Ancho]]+Sheet1!$U$2)*(Main[[#This Row],[Alto]]+Sheet1!$U$2))/6000)) -> 5.0575 | W12: =ROUNDUP(((Main[[#This Row],[Volumen]]*5.25))*1.36,2) -> 36.12 | X12: 0.1586 | Y12: =Main[[#This Row],[Cantidad_Min]]*Main[[#This Row],[Precio]]*Main[[#This Row],[Qty]] -> 338 | Z12: =_xlfn.XLOOKUP(Main[[#This Row],[Finca]], Fincas[Nombre], Fincas[ID]) -> 75 | AA12: {=_xlfn.LET( _xlpm.txt, Main[[#This Row],[Standing Orders]], _xlpm.q2num, IFERROR(VALUE(Guias!$M$2), ""), _xlpm.q2txt, UPPER(Guias!$M$2), _xlpm.weekIsOdd, IF(_xlpm.q2num<>"", MOD(_xlpm.q2num,2)=1, IF(ISNUMBER(FIND("IMPAR", _xlpm.q2txt)), TRUE, IF(ISNUMBER(FIND("PAR", _xlpm.q2txt)), FALSE, TRUE))), _xlpm.parts, IF(TRIM(_xlpm.txt)="", "", _xlfn.TOCOL(_xlfn.TEXTSPLIT(SUBSTITUTE(_xlpm.txt, CHAR(160), " "), ";"), 1)), _xlpm.build, IF(_xlfn.VALUETOTEXT(_xlpm.parts)="", "", _xlfn.MAP(_xlpm.parts, _xlfn.LAMBDA(_xlpm.r, _xlfn.LET( _xlpm.s, TRIM(_xlpm.r), _xlpm.s_upper, UPPER(_xlpm.s), _xlpm.p_marker, IF(ISNUMBER(FIND("(*IMPAR)", _xlpm.s_upper)), "impar", IF(ISNUMBER(FIND("(*PAR)", _xlpm.s_upper)), "par", "")), _xlpm.allow, IF(_xlpm.p_marker="", TRUE, IF(_xlpm.p_marker="impar", _xlpm.weekIsOdd, NOT(_xlpm.weekIsOdd))), IF(NOT(_xlpm.allow), "", _xlfn.LET( _xlpm.num, IFERROR(VALUE(LEFT(_xlpm.s, FIND(" ", _xlpm.s & " ")-1)), 0), _xlpm.rawname, TRIM(IFERROR(_xlfn.TEXTAFTER(_xlpm.s, " "), "")), _xlpm.name_pre, IFERROR(_xlfn.TEXTBEFORE(_xlpm.rawname, "["), _xlpm.rawname), _xlpm.name, TRIM(IFERROR(_xlfn.TEXTBEFORE(_xlpm.name_pre, "("), _xlpm.name_pre)), _xlpm.id, _xlfn.XLOOKUP(_xlpm.name, Vendedores[Fragmento], Vendedores[ID], ""), IF(OR(_xlpm.id="", _xlpm.num<=0), "", LEFT(REPT(_xlpm.id & ",", _xlpm.num), LEN(REPT(_xlpm.id & ",", _xlpm.num)) - 1)) ) ) ) ))), _xlpm.resultado, _xlfn.TEXTJOIN(",", TRUE, _xlpm.build), IF(_xlpm.resultado="", "", _xlpm.resultado & ",") )} | AB12: Y
